Workbook
Name Cantidades: Tabla1[Cantidad]
Name SegmentaciónDeDatos_Categoría: #N/A
Name SegmentaciónDeDatos_Forma_de_Pago: #N/A
Name SegmentaciónDeDatos_Forma_de_Pago1: #N/A
Name SegmentaciónDeDatos_Local: #N/A
Name SegmentaciónDeDatos_Local1: #N/A
Name SegmentaciónDeDatos_Marca: #N/A
Name SegmentaciónDeDatos_Vendedor: #N/A
Name Totales: Tabla1[Total]

Sheet EJERCICIO 1
A1: APLICAR FORMATO CONDICIONAL SEGÚN INDICA LOS ENCABEZADOS DE COLUMNAS
A2: 10 superiores | B2: 10 inferiores | C2: 20% valores superiores | D2: 20% valores inferiores | E2: Encima del promedio | F2: Debajo del promedio
A3: 72 | B3: 45 | C3: 85 | D3: 49 | E3: 39 | F3: 71
A4: 32 | B4: 73 | C4: 0 | D4: 63 | E4: 21 | F4: 93
A5: 98 | B5: 96 | C5: 99 | D5: 46 | E5: 16 | F5: 81
A6: 18 | B6: 81 | C6: 36 | D6: 63 | E6: 96 | F6: 75
A7: 35 | B7: 27 | C7: 17 | D7: 53 | E7: 63 | F7: 43
A8: 46 | B8: 82 | C8: 0 | D8: 32 | E8: 20 | F8: 1
A9: 96 | B9: 67 | C9: 63 | D9: 48 | E9: 74 | F9: 87
A10: 85 | B10: 32 | C10: 80 | D10: 18 | E10: 73 | F10: 13
A11: 47 | B11: 92 | C11: 8 | D11: 51 | E11: 85 | F11: 8
A12: 70 | B12: 81 | C12: 79 | D12: 58 | E12: 36 | F12: 99
A13: 70 | B13: 23 | C13: 35 | D13: 4 | E13: 89 | F13: 90
A14: 62 | B14: 87 | C14: 46 | D14: 76 | E14: 75 | F14: 1
... A21: 78 | B21: 100 | C21: 25 | D21: 42 | E21: 66 | F21: 35

Sheet EJERCICIO 2
A1: MESES | B1: JULIO | C1: AGOSTO | D1: SEPTIEMBRE | E1: OCTUBRE | F1: NOVIEMBRE | G1: DICIEMBRE
A2: Pedro Martinez | B2: 8908.8 | C2: =B2+890 -> 9798.8 | D2: =C2+890 -> 10688.8 | E2: =D2+890 -> 11578.8 | F2: =E2+890 -> 12468.8 | G2: =F2+890 -> 13358.8
A3: Maria Garcia | B3: 3453.34 | C3: =B3+890 -> 4343.34 | D3: =C3+890 -> 5233.34 | E3: =D3+890 -> 6123.34 | F3: =E3+890 -> 7013.34 | G3: =F3+890 -> 7903.34
A4: Alberto Jimenez | B4: 3291.81 | C4: =B4+890 -> 4181.81 | D4: =C4+890 -> 5071.81 | E4: =D4+890 -> 5961.81 | F4: =E4+890 -> 6851.81 | G4: =F4+890 -> 7741.81
A5: Juana Rodriguez | B5: 6688 | C5: =B5+890 -> 7578 | D5: =C5+890 -> 8468 | E5: =D5+890 -> 9358 | F5: =E5+890 -> 10248 | G5: =F5+890 -> 11138
A8: Resaltar los valores mayores a $6.000

Sheet EJERCICIO 3
A1: PAIS | B1: ENERO | C1: FEBRERO | D1: MARZO | E1: ABRIL | F1: MAYO | G1: JUNIO | H1: TOTAL | I1: MAXIMO | J1: MINIMO | K1: PROMEDIO
A3: ESPAÑA | B3: 150 | C3: 130 | D3: 175 | E3: 210 | F3: 145 | G3: 165
A4: ITALIA | B4: 130 | C4: 191 | D4: 180 | E4: 160 | F4: 185 | G4: 265
A5: FRANCIA | B5: 150 | C5: 210 | D5: 130 | E5: 134 | F5: 120 | G5: 156
A6: PORTUGAL | B6: 89 | C6: 100 | D6: 105 | E6: 110 | F6: 105 | G6: 103
A7: SUIZA | B7: 34 | C7: 56 | D7: 76 | E7: 66 | F7: 55 | G7: 88
A10: TOTAL
A16: LOS VALORES EN EL RANGO B3:K7 DEBERAN TENER LOS SIGUIENTES COLORES:
A18: SI ESTAN POR DEBAJO DE 100, DEBERAN TENER COLOR AZUL
A19: SI ESTAN ENTRE 100 Y 170, TENDRAN COLOR NARANJA
A20: SI ESTAN POR ENCIMA DE 170, TENDRAN COLOR VERDE

Sheet Tablas dinámicas comercial
A3: Etiquetas de fila | B3: Suma de Total | C3: Suma de Cantidad | E3: Suma de Total
A4: RADIO DRK-30 | B4: 290 | C4: 10 | E4: 6461271
A5: RADIOGRABADOR | B5: 356 | C5: 4
A6: TV COLOR FLAT 21" | B6: 4245 | C6: 5
A7: RADIO RELOJ CR-001 | B7: 6591 | C7: 169
A8: RADIOGRABADOR | B8: 10680 | C8: 120 | E8: Suma de Cantidad
A9: BATIDORA MANUAL | B9: 12555 | C9: 81 | E9: 8398
A10: TV COLOR 14" | B10: 17970 | C10: 30
A11: CAFETERA | B11: 19206 | C11: 194
A12: DEPILADORA | B12: 28290 | C12: 210 | E12: Promedio de Ticket
A13: TV COLOR 20" | B13: 30825 | C13: 45 | E13: =GETPIVOTDATA("suma total",$E$15)/GETPIVOTDATA("Suma de Cantidad",$E$15) -> 769.38211
A14: PROCESADORA | B14: 36660 | C14: 188
A15: LICUADORA | B15: 55086 | C15: 634 | E15: suma total | F15: Suma de Cantidad | G15: Suma de Ticket Promedio
A16: REPRODUCTOR MP3 | B16: 83066 | C16: 614 | E16: 6461271 | F16: 8398 | G16: 769.38211
A17: AIRE ACONDICIONADO | B17: 119567 | C17: 133
A18: SECARROPAS | B18: 282007 | C18: 373
A19: FREEZER | B19: 307872 | C19: 328
A20: REPRODUCTOR DE DVD | B20: 323925 | C20: 1215
A21: MICROONDAS | B21: 329658 | C21: 282
A22: HELADERA | B22: 372478 | C22: 382
A23: REPRODUCTOR Y GRABADORA DE DVD | B23: 372627 | C23: 373
A24: LAVARROPAS | B24: 510935 | C24: 435
A25: TV COLOR FLAT 21" + REPRODUCTOR DE DVD | B25: 521011 | C25: 514
A26: LAVAVAJILLAS | B26: 951051 | C26: 449
A27: COCINA | B27: 1009459 | C27: 841
A28: HELADERA CON FREEZER | B28: 1054861 | C28: 769
A29: Total general | B29: 6461271 | C29: 8398
A34: Etiquetas de fila | B34: Suma de Total | D34: Etiquetas de fila | E34: Suma de Total
A35: Caballito | B35: 1244140 | D35: Efectivo | E35: 3706843
A36: Liniers | B36: 1176028 | D36: Tarjeta | E36: 2754428
A37: Alto Palermo | B37: 1045443 | D37: Total general | E37: 6461271
A38: Abasto | B38: 1039774
A39: Centro | B39: 1013346
A40: Unicenter | B40: 942540
A41: Total general | B41: 6461271
A45: Etiquetas de fila | B45: Suma de Total | E45: Etiquetas de columna
A46: PHILIPS | B46: 1851827 | E46: Línea Blanca | F46: TV/Video/DVD | G46: Electro | H46: Aire Acondicionado | I46: Audio | J46: Depiladoras | K46: Total general
A47: WHIRLPOOL | B47: 1186789 | D47: Suma de Total | E47: 4818321 | F47: 1270603 | G47: 123507 | H47: 119567 | I47: 100983 | J47: 28290 | K47: 6461271
A48: GAFA | B48: 982174
A49: AUDIOLOGIC | B49: 702210
...

Sheet Planilla de ventas por local
A1: Fecha Venta | B1: Producto | C1: Marca | D1: Categoría | E1: Local | F1: Vendedor | G1: Forma de Pago | H1: Precio | I1: Cantidad | J1: Total | K1: Columna1
A2: 43324 | B2: LAVAVAJILLAS | C2: AUDIOLOGIC | D2: Línea Blanca | E2: Liniers | F2: Ggonzalez | G2: Tarjeta | H2: 2279 | I2: 5 | J2: =H2*I2 -> 11395 | K2: =IF(H2*I2=J2,"SI","Error") -> SI
A3: 43324 | B3: HELADERA CON FREEZER | C3: GAFA | D3: Línea Blanca | E3: Abasto | F3: Avergara | G3: Efectivo | H3: 1579 | I3: 15 | J3: =H3*I3 -> 23685 | K3: =IF(H3*I3=J3,"SI","Error") -> SI
A4: 43324 | B4: HELADERA CON FREEZER | C4: PHILIPS | D4: Línea Blanca | E4: Centro | F4: Srambaldo | G4: Efectivo | H4: 1579 | I4: 6 | J4: =H4*I4 -> 9474 | K4: =IF(H4*I4=J4,"SI","Error") -> SI
A5: 43324 | B5: COCINA | C5: AUDIOLOGIC | D5: Línea Blanca | E5: Caballito | F5: Mnarduzzi | G5: Efectivo | H5: 1399 | I5: 36 | J5: =H5*I5 -> 50364 | K5: =IF(H5*I5=J5,"SI","Error") -> SI
A6: 43324 | B6: HELADERA CON FREEZER | C6: WHIRLPOOL | D6: Línea Blanca | E6: Abasto | F6: Dsandoval | G6: Tarjeta | H6: 1279 | I6: 7 | J6: =H6*I6 -> 8953 | K6: =IF(H6*I6=J6,"SI","Error") -> SI
A7: 43324 | B7: HELADERA CON FREEZER | C7: PHILIPS | D7: Línea Blanca | E7: Liniers | F7: Ggonzalez | G7: Efectivo | H7: 1279 | I7: 45 | J7: =H7*I7 -> 57555 | K7: =IF(H7*I7=J7,"SI","Error") -> SI
A8: 43324 | B8: LAVARROPAS | C8: GAFA | D8: Línea Blanca | E8: Alto Palermo | F8: Ccarrizo | G8: Efectivo | H8: 1259 | I8: 35 | J8: =H8*I8 -> 44065 | K8: =IF(H8*I8=J8,"SI","Error") -> SI
A9: 43324 | B9: COCINA | C9: DATSUN | D9: Línea Blanca | E9: Alto Palermo | F9: Lzeppa | G9: Efectivo | H9: 1249 | I9: 6 | J9: =H9*I9 -> 7494 | K9: =IF(H9*I9=J9,"SI","Error") -> SI
A10: 43324 | B10: COCINA | C10: NOBLEX | D10: Línea Blanca | E10: Alto Palermo | F10: Lzeppa | G10: Tarjeta | H10: 1249 | I10: 6 | J10: =H10*I10 -> 7494 | K10: =IF(H10*I10=J10,"SI","Error") -> SI
A11: 43324 | B11: COCINA | C11: DATSUN | D11: Línea Blanca | E11: Unicenter | F11: Abrieva | G11: Efectivo | H11: 1249 | I11: 45 | J11: =H11*I11 -> 56205 | K11: =IF(H11*I11=J11,"SI","Error") -> SI
A12: 43324 | B12: COCINA | C12: PHILIPS | D12: Línea Blanca | E12: Unicenter | F12: Abrieva | G12: Tarjeta | H12: 1249 | I12: 36 | J12: =H12*I12 -> 44964 | K12: =IF(H12*I12=J12,"SI","Error") -> SI
A13: 43324 | B13: MICROONDAS | C13: DATSUN | D13: Línea Blanca | E13: Unicenter | F13: Scorrales | G13: Tarjeta | H13: 1169 | I13: 35 | J13: =H13*I13 -> 40915 | K13: =IF(H13*I13=J13,"SI","Error") -> SI
... A409: 43334 | B409: REPRODUCTOR MP3 | C409: WHIRLPOOL | D409: Audio | E409: Unicenter | F409: Abrieva | G409: Tarjeta | H409: 129 | I409: 35 | J409: =H409*I409 -> 4515 | K409: =IF(H409*I409=J409,"SI","Error") -> SI

Sheet Tablas dinámicas vendedores
A2: Etiquetas de fila | B2: Suma de Total | D2: Etiquetas de fila | E2: Suma de Cantidad | G2: Suma de Total | H2: Suma de Cantidad | I2: Suma de Promedio de venta por vendedor
A3: Abrieva | B3: 382443 | D3: Esaralegui | E3: 151 | G3: 6461271 | H3: 8398 | I3: 769.38211
A4: Agomez | B4: 356018 | D4: Avergara | E4: 261
A5: Avergara | B5: 253969 | D5: Mnoguera | E5: 341
A6: Ccarrizo | B6: 376316 | D6: Agomez | E6: 362 | G6: Etiquetas de fila | H6: Suma de Total
A7: Dacosta | B7: 419230 | D7: Srambaldo | E7: 369 | G7: Efectivo | H7: 3706843
A8: Dsandoval | B8: 341962 | D8: Mloibiso | E8: 382 | G8: Tarjeta | H8: 2754428
A9: Esaralegui | B9: 100734 | D9: Jlopez | E9: 431 | G9: Total general | H9: 6461271
A10: Fcasco | B10: 414845 | D10: Ccarrizo | E10: 434
A11: Ggonzalez | B11: 527633 | D11: Dsandoval | E11: 471
A12: Jlopez | B12: 320279 | D12: Fcasco | E12: 475
A13: Lzeppa | B13: 503623 | D13: Abrieva | E13: 512 | G13: Suma de Total
A14: Mloibiso | B14: 165504 | D14: Lzeppa | E14: 542 | G14: 6461271
A15: Mnarduzzi | B15: 829295 | D15: Ggonzalez | E15: 573
A16: Mnatalini | B16: 443843 | D16: Mnatalini | E16: 627
A17: Mnoguera | B17: 229165 | D17: Dacosta | E17: 655 | G17: Suma de Cantidad
A18: Scorrales | B18: 459363 | D18: Scorrales | E18: 697 | G18: 8398
A19: Srambaldo | B19: 337049 | D19: Mnarduzzi | E19: 1115
A20: Total general | B20: 6461271 | D20: Total general | E20: 8398
B23: Etiquetas de fila | C23: Suma de Total | E23: Etiquetas de fila | F23: Suma de Ticket Promedio
B24: Mnarduzzi | C24: 829295 | E24: Abrieva | F24: 746.95898
B25: Ggonzalez | C25: 527633 | E25: Agomez | F25: 983.47514
B26: Lzeppa | C26: 503623 | E26: Avergara | F26: 973.0613
B27: Scorrales | C27: 459363 | E27: Ccarrizo | F27: 867.08756
B28: Mnatalini | C28: 443843 | E28: Dacosta | F28: 640.0458
B29: Dacosta | C29: 419230 | E29: Dsandoval | F29: 726.03397
B30: Fcasco | C30: 414845 | E30: Esaralegui | F30: 667.11258
B31: Abrieva | C31: 382443 | E31: Fcasco | F31: 873.35789
B32: Ccarrizo | C32: 376316 | E32: Ggonzalez | F32: 920.82548
B33: Agomez | C33: 356018 | E33: Jlopez | F33: 743.10673
B34: Dsandoval | C34: 341962 | E34: Lzeppa | F34: 929.19373
B35: Srambaldo | C35: 337049 | E35: Mloibiso | F35: 433.25654
... B41: Total general | C41: 6461271 | E41: Total general | F41: 769.38211

Sheet Dashboard Comercial
B1: TOTAL DE VENTAS | E1: TOTAL CANTIDADES | H1: TICKET PROMEDIO
B3: =GETPIVOTDATA("Total",'Tablas dinámicas comercial'!$E$3) -> 6461271 | E3: =GETPIVOTDATA("Cantidad",'Tablas dinámicas comercial'!$E$8) -> 8398 | H3: =GETPIVOTDATA("Suma de Ticket Promedio",'Tablas dinámicas comercial'!$E$15) -> 769.38211

Sheet Dashboard de vendedores
B2: Total Vendido | F2: Total Cantidades | I2: Promedio de Ticket
B3: =GETPIVOTDATA("Suma de Total",'Tablas dinámicas vendedores'!$G$2) -> 6461271 | F3: =GETPIVOTDATA("Cantidad",'Tablas dinámicas vendedores'!$G$17) -> 8398 | I3: =GETPIVOTDATA("Suma de Promedio de venta por vendedor",'Tablas dinámicas vendedores'!$G$2) -> 769.38211
